Workbook
Name _1Excel_BuiltIn_Print_Area_2: NA()
Name _4Z_FE2C2EAB_4123_4290_86BA_08E4AC7C24C1_.wvu.Rows_1: ([1]DCF!#REF!,[1]DCF!#REF!,[1]DCF!$18:$19)
Name _4Z_FE2C2EAB_4123_4290_86BA_08E4AC7C24C1_.wvu.Rows_1: ([1]DCF!#REF!,[1]DCF!#REF!,[1]DCF!$18:$19)
Name _4Z_FE2C2EAB_4123_4290_86BA_08E4AC7C24C1_.wvu.Rows_1: ([1]DCF!#REF!,[1]DCF!#REF!,[1]DCF!$18:$19)
Name _4Z_FE2C2EAB_4123_4290_86BA_08E4AC7C24C1_.wvu.Rows_1: ([1]DCF!#REF!,[1]DCF!#REF!,[1]DCF!$18:$19)
Name BC: #REF!
Name BC: #REF!
Name BC: #REF!
Name CF: [2]MHPP!#REF!
Name CF: [2]MHPP!#REF!
Name CF: [2]MHPP!#REF!
Name EMITEN: 'DAFTAR EMITEN 2023'!$B$1:$D$964
Name Jadwal: #REF!
Name Jadwal: #REF!
Name Jadwal: #REF!
Name MULTIPLE: 'PASAR KESEBANDINGAN'!$C$40:$C$44
Name MULTIPLES: 'PASAR KESEBANDINGAN'!$C$40:$N$44
Name PRINT_AREA_MI: NA()
Name RPP: #REF!
Name RPP: #REF!
Name RPP: #REF!
Name RPP: #REF!
Name Slicer_Cash_Flow_Indicator: #N/A
Name Slicer_Leverage_Ratio: #N/A
Name Slicer_Liquidity_Measurement_Ratio: #N/A
Name Slicer_Ratio: #N/A
Name Z_AC236A6A_632A_43B1_B283_C6312913D85E_.wvu.PrintArea: #REF!
Name Z_AC236A6A_632A_43B1_B283_C6312913D85E_.wvu.PrintArea: #REF!
Name Z_AC236A6A_632A_43B1_B283_C6312913D85E_.wvu.PrintArea: #REF!
Name Z_AC236A6A_632A_43B1_B283_C6312913D85E_.wvu.Rows: [1]DCF!#REF!
Name Z_AC236A6A_632A_43B1_B283_C6312913D85E_.wvu.Rows: [1]DCF!#REF!
Name Z_AC236A6A_632A_43B1_B283_C6312913D85E_.wvu.Rows: [1]DCF!#REF!
Name Z_FE2C2EAB_4123_4290_86BA_08E4AC7C24C1_.wvu.PrintArea: #REF!
Name Z_FE2C2EAB_4123_4290_86BA_08E4AC7C24C1_.wvu.PrintArea: #REF!
Name Z_FE2C2EAB_4123_4290_86BA_08E4AC7C24C1_.wvu.PrintArea: #REF!
Name Z_FE2C2EAB_4123_4290_86BA_08E4AC7C24C1_.wvu.Rows: (#REF!,#REF!)
Name Z_FE2C2EAB_4123_4290_86BA_08E4AC7C24C1_.wvu.Rows: (#REF!,#REF!)
Name Z_FE2C2EAB_4123_4290_86BA_08E4AC7C24C1_.wvu.Rows: (#REF!,#REF!)

Sheet CATATAN FINAL
A1: CATATAN FINAL - OVERWRITE WORKBOOK
A2: Sheet ini mendokumentasikan cell yang diubah/update/sesuaikan pada workbook final. Seluruh cell target pada sheet asal diberi font merah.
A3: No. | B3: Timestamp | C3: Sheet | D3: Cell | E3: Before | F3: After | G3: Tujuan Cell | H3: Alasan Perubahan / Judgment | I3: Formula? | J3: Font Merah?
A4: 1 | B4: 2026-04-30 09:30:15 | C4: HOME | D4: B7 | E4: 1610000000 | F4: '=B6 | G4: Jumlah saham dinilai | H4: Valuation objective is 100% equity on controlling, marketable basis. | I4: Ya | J4: Ya
A5: 2 | B5: 2026-04-30 09:30:15 | C5: HOME | D5: B15 | E5: '=DLOM!F34 | F5: '=STAT_ASSUMPTIONS!B15 | G5: DLOM input | H5: DLOM is not applied under final instruction. | I5: Ya | J5: Ya
A6: 3 | B6: 2026-04-30 09:30:15 | C6: HOME | D6: B16 | E6: '='DLOC(PFC)'!E25 | F6: '=STAT_ASSUMPTIONS!B15 | G6: DLOC/PFC input | H6: DLOC/minority/control discount is not applied under final instruction. | I6: Ya | J6: Ya
A7: 4 | B7: 2026-04-30 09:30:15 | C7: BALANCE SHEET | D7: B46 | E7: Current Profit (Laba Usaha Tahun Berjalan 2021) | F7: Current Profit - Commercial NPAT (Laba Bersih Komersial) | G7: Current profit label | H7: Clarifies that earning/current profit basis is commercial, not fiscal. | I7: Tidak | J7: Ya
A8: 5 | B8: 2026-04-30 09:30:15 | C8: BALANCE SHEET | D8: C46 | E8: 619603684 | F8: '='INCOME STATEMENT'!C35 | G8: Retained earnings current profit | H8: Commercial NPAT is used as the current profit reference; fiscal current profit is not earning power. | I8: Ya | J8: Ya
A9: 6 | B9: 2026-04-30 09:30:15 | C9: BALANCE SHEET | D9: D46 | E9: 1205375265 | F9: '='INCOME STATEMENT'!D35 | G9: Retained earnings current profit | H9: Commercial NPAT is used as the current profit reference; fiscal current profit is not earning power. | I9: Ya | J9: Ya
A10: 7 | B10: 2026-04-30 09:30:15 | C10: BALANCE SHEET | D10: E46 | E10: 2590960070 | F10: '='INCOME STATEMENT'!E35 | G10: Retained earnings current profit | H10: Commercial NPAT is used as the current profit reference; fiscal current profit is not earning power. | I10: Ya | J10: Ya
A11: 8 | B11: 2026-04-30 09:30:15 | C11: BALANCE SHEET | D11: C47 | E11: '=+C46+C45 | F11: '=+C46+C45 | G11: Dependent balance/equity output | H11: Formula result changes because current profit basis was corrected to commercial NPAT. | I11: Ya | J11: Ya
A12: 9 | B12: 2026-04-30 09:30:15 | C12: BALANCE SHEET | D12: D47 | E12: '=+D46+D45 | F12: '=+D46+D45 | G12: Dependent balance/equity output | H12: Formula result changes because current profit basis was corrected to commercial NPAT. | I12: Ya | J12: Ya
A13: 10 | B13: 2026-04-30 09:30:15 | C13: BALANCE SHEET | D13: E47 | E13: '=+E46+E45 | F13: '=+E46+E45 | G13: Dependent balance/equity output | H13: Formula result changes because current profit basis was corrected to commercial NPAT. | I13: Ya | J13: Ya
A14: 11 | B14: 2026-04-30 09:30:15 | C14: BALANCE SHEET | D14: C48 | E14: '=+C42+C47+C43 | F14: '=+C42+C47+C43 | G14: Dependent balance/equity output | H14: Formula result changes because current profit basis was corrected to commercial NPAT. | I14: Ya | J14: Ya
A15: 12 | B15: 2026-04-30 09:30:15 | C15: BALANCE SHEET | D15: D48 | E15: '=+D42+D47+D43 | F15: '=+D42+D47+D43 | G15: Dependent balance/equity output | H15: Formula result changes because current profit basis was corrected to commercial NPAT. | I15: Ya | J15: Ya
... A147: 144 | B147: 2026-04-30 09:30:15 | C147: ROIC | D147: F9 | E147: Asumsi ini sesuai dengan Laporan Penilaian Wajib Pajak bahwa Kas dan Deposito adalah Non Operating Asset | F147: Non-operating fixed assets remain zero unless idle assets are specifically identified. | G147: ROIC note | H147: No evidence of idle/non-operating fixed assets was available. | I147: Tidak | J147: Ya
A148: 145 | B148: 2026-04-30 09:30:15 | C148: ROIC | D148: F10 | F148: Cash and bank/deposit treated as excess cash; minimum operating cash remains a judgment sensitivity. | G148: ROIC note | H148: Documents the cash classification judgment directly beside the formula. | I148: Tidak | J148: Ya
A149: 146 | B149: 2026-04-30 09:30:15 | C149: ROIC | D149: B12 | E149: '=SUM(B8:B11) | F149: '=SUM(B8:B11) | G149: ROIC dependent output | H149: Dependent output from corrected excess cash formula. | I149: Ya | J149: Ya
A150: 147 | B150: 2026-04-30 09:30:15 | C150: ROIC | D150: C12 | E150: '=SUM(C8:C11) | F150: '=SUM(C8:C11) | G150: ROIC dependent output | H150: Dependent output from corrected excess cash formula. | I150: Ya | J150: Ya
A151: 148 | B151: 2026-04-30 09:30:15 | C151: ROIC | D151: D12 | E151: '=SUM(D8:D11) | F151: '=SUM(D8:D11) | G151: ROIC dependent output | H151: Dependent output from corrected excess cash formula. | I151: Ya | J151: Ya
A152: 149 | B152: 2026-04-30 09:30:15 | C152: ROIC | D152: C13 | E152: '=B12 | F152: '=B12 | G152: ROIC dependent output | H152: Dependent output from corrected excess cash formula. | I152: Ya | J152: Ya
A153: 150 | B153: 2026-04-30 09:30:15 | C153: ROIC | D153: D13 | E153: '=C12 | F153: '=C12 | G153: ROIC dependent output | H153: Dependent output from corrected excess cash formula. | I153: Ya | J153: Ya
A154: 151 | B154: 2026-04-30 09:30:15 | C154: ROIC | D154: C15 | E154: '=C7/C13 | F154: '=C7/C13 | G154: ROIC dependent output | H154: Dependent output from corrected excess cash formula. | I154: Ya | J154: Ya
A155: 152 | B155: 2026-04-30 09:30:15 | C155: ROIC | D155: D15 | E155: '=D7/D13 | F155: '=D7/D13 | G155: ROIC dependent output | H155: Dependent output from corrected excess cash formula. | I155: Ya | J155: Ya
A156: 153 | B156: 2026-04-30 09:30:15 | C156: EEM | D156: D7 | E156: '=AAM!E16+AAM!E22-(AAM!E29+AAM!E30+AAM!E31+AAM!E36)-AAM!E9 | F156: '='STAT_EEM'!B7 | G156: Net operating tangible asset base | H156: Uses final operating NTA: fixed assets net plus operating NWC. | I156: Ya | J156: Ya
A157: 154 | B157: 2026-04-30 09:30:15 | C157: EEM | D157: C8 | E157: '='BORROWING CAP'!F14 | F157: '='STAT_EEM'!B15 | G157: Return on tangible asset | H157: Uses workbook-derived return on NTA from final EEM assumptions. | I157: Ya | J157: Ya
A158: 155 | B158: 2026-04-30 09:30:15 | C158: EEM | D158: D9 | E158: '=+D7*C8 | F158: '=D7*C8 | G158: Required return on NTA | H158: Required return must be charged against operating tangible assets. | I158: Ya | J158: Ya
A159: 156 | B159: 2026-04-30 09:30:15 | C159: EEM | D159: D12 | E159: '=NOPLAT!E19 | F159: '='STAT_EEM'!B14 | G159: Normalized NOPLAT | H159: Uses commercial EBIT taxed at statutory 22%; no fiscal correction. | I159: Ya | J159: Ya
A160: 157 | B160: 2026-04-30 09:30:15 | C160: EEM | D160: D13 | E160: '='FIXED ASSET'!E51 | F160: '=0 | G160: Depreciation add-back | H160: EEM excess earnings is based on normalized NOPLAT, not historical FCF with 2021 WC release. | I160: Ya | J160: Ya
... A189: 186 | B189: 2026-04-30 09:30:15 | C189: DCF | D189: F5 | E189: '=E5+1 | F189: '=E5+1 | G189: Projection year | H189: Expands DCF explicit period to 2022E-2026E. | I189: Ya | J189: Ya
A190: 187 | B190: 2026-04-30 09:30:15 | C190: DCF | D190: G5 | F190: '=F5+1 | G190: Projection year | H190: Expands DCF explicit period to 2022E-2026E. | I190: Ya | J190: Ya
A191: 188 | B191: 2026-04-30 09:30:15 | C191: DCF | D191: H5 | F191: '=G5+1 | G191: Projection year | H191: Expands DCF explicit period to 2022E-2026E. | I191: Ya | J191: Ya
A192: 189 | B192: 2026-04-30 09:30:15 | C192: DCF | D192: A12 | E192: (Increase) Decrease in Current Asset | F192: Less: Change in Operating NWC | G192: DCF working capital label | H192: DCF uses operating NWC change from final STAT_DCF model. | I192: Tidak | J192: Ya
A193: 190 | B193: 2026-04-30 09:30:15 | C193: DCF | D193: A13 | E193: Increase (Decrease) in Current Liabilities | F193: Operating WC detail included in row 12 | G193: DCF working capital label | H193: Prevents old current-asset/current-liability wording from implying total current assets/liabilities. | I193: Tidak | J193: Ya
A194: 191 | B194: 2026-04-30 09:30:15 | C194: DCF | D194: C7 | E194: '=NOPLAT!E19 | F194: '=STAT_DCF!B15 | G194: DCF NOPLAT | H194: Uses final commercial statutory 22% NOPLAT. | I194: Ya | J194: Ya
A195: 192 | B195: 2026-04-30 09:30:15 | C195: DCF | D195: C8 | E195: '='FIXED ASSET'!E51 | F195: '=STAT_DCF!B26 | G195: DCF D&A add-back | H195: Uses D&A add-back from final STAT_DCF. | I195: Ya | J195: Ya
A196: 193 | B196: 2026-04-30 09:30:15 | C196: DCF | D196: C9 | E196: '=+C7+C8 | F196: '=C7+C8 | G196: DCF gross cash flow | H196: Formula subtotal from final NOPLAT and D&A. | I196: Ya | J196: Ya
A197: 194 | B197: 2026-04-30 09:30:15 | C197: DCF | D197: C12 | E197: '='CASH FLOW STATEMENT'!E8 | F197: '=0 | G197: Base-period NWC change | H197: No base-period NWC change in valuation cash-flow projection. | I197: Ya | J197: Ya
A198: 195 | B198: 2026-04-30 09:30:15 | C198: DCF | D198: C13 | E198: '='CASH FLOW STATEMENT'!E9 | F198: '=0 | G198: DCF operating WC detail placeholder | H198: Operating WC movement is consolidated in row 12. | I198: Ya | J198: Ya
A199: 196 | B199: 2026-04-30 09:30:15 | C199: DCF | D199: C14 | E199: '='CASH FLOW STATEMENT'!E10 | F199: '=SUM(C12:C13) | G199: DCF total NWC cash-flow effect | H199: Keeps the original subtotal structure. | I199: Ya | J199: Ya
...

Sheet HOME
A1: KERTAS KERJA PENILAIAN BISNIS
A4: Nama Objek Pajak | B4: Makmur Jaya Sejati Raya
A5: NPWP Objek Pajak | B5: 211437892119000
A6: Sektor Perusahaan | B6: Consumer Cyclicals | D6: Basic Materials | E6: Orang Pribadi
A7: Jenis Perusahaan | B7: Tertutup | D7: Consumer Cyclicals | E7: Badan
A9: Nama Subjek Pajak | B9: Helga | D9: Consumer Non-Cyclicals
A10: NPWP Subjek Pajak | B10: 211437892119000 | D10: Energy | E10: Lembar Saham
A11: Jenis Subjek Pajak | B11: Orang Pribadi | E11: Modal Disetor
A12: Jenis Kepemilikan Saham | B12: Minoritas
A14: Jenis Peralihan yang Diketahui | B14: Modal Disetor
A15: =IF(B14="Modal Disetor","Jumlah Modal Disetor 100%","Jumlah Saham Beredar 100%") -> Jumlah Modal Disetor 100% | B15: 5280000000 | D15: Financials | E15: Saham
A16: =IF(B14="Modal Disetor","Jumlah Modal Disetor yang Dinilai","Jumlah Saham yang Dinilai") -> Jumlah Modal Disetor yang Dinilai | B16: 1600000000 | D16: Healthcare | E16: Bisnis
A17: =IF(B14="Modal Disetor","Proporsi Modal Disetor yang Dinilai","Proporsi Saham yang Dinilai") -> Proporsi Modal Disetor yang Dinilai | B17: =IF(B16/B15>100%,"Data Tidak Valid",IF(B16/B15<=0,"Data Tidak Valid",B16/B15)) -> 0.3030303 | D17: Industrials
A19: Tahun Transaksi Pengalihan | B19: 2022 | D19: Infrastructures
A20: Cut off Date | B20: =DATE(B19-1, 12, 31) -> 44561 | D20: Properties & Real Estate
A21: Akhir Periode Proyeksi Pertama | B21: =DATE(B19, 12, 31) -> 44926 | D21: Transportation & Logistic
A22: Objek Penilaian | B22: Saham | D22: Technology
A24: Tahun Pengalihan | B24: =YEAR(B20) -> 2021 | D24: Tertutup
A25: DISCOUNT LACK OF MARKETABILITY | B25: =STAT_ASSUMPTIONS!B15 -> 0 | D25: Terbuka (Tbk)
A26: DISCOUNT LACK OF CONTROL/PREMIUM FOR CONTROL | B26: =STAT_ASSUMPTIONS!B15 -> 0
A28: LAPORAN KEUANGAN HISTORIS | B28: PERTIMBANGAN | C28: PROYEKSI | D28: PENDEKATAN PENILAIAN | E28: KESIMPULAN

Sheet DAFTAR EMITEN 2023
A1: 1 | B1: AADI | C1: PT Adaro Andalan Indonesia Tbk | D1: 05 Des 2024
A2: 2 | B2: AALI | C2: Astra Agro Lestari Tbk | D2: 09 Des 1997
A3: 3 | B3: ABBA | C3: Mahaka Media Tbk | D3: 37349
A4: 4 | B4: ABDA | C4: Asuransi Bina Dana Arta Tbk | D4: 32695
A5: 5 | B5: ABMM | C5: ABM Investama Tbk | D5: 06 Des 2011
A6: 6 | B6: ACES | C6: PT Aspirasi Hidup Indonesia Tbk | D6: 39392
A7: 7 | B7: ACRO | C7: PT Samcro Hyosung Adilestari Tbk. | D7: 45302
A8: 8 | B8: ACST | C8: PT Acset Indonusa Tbk. | D8: 41449
A9: 9 | B9: ADCP | C9: PT Adhi Commuter Properti Tbk | D9: 21 Mei 2021
A10: 10 | B10: ADES | C10: Akasha Wira International Tbk Tbk | D10: 34498
A11: 11 | B11: ADHI | C11: PT Adhi Karya (Persero) Tbk. | D11: 38064
A12: 12 | B12: ADMF | C12: Adira Dinamika Multi Finance Tbk | D12: 38077
A13: 13 | B13: ADMG | C13: Polychem Indonesia Tbk | D13: 20 Okt 1993
A14: 14 | B14: ADMR | C14: PT Alamtri Minerals Indonesia Tbk | D14: 44564
A15: 15 | B15: ADRO | C15: Alamtri Resources Indonesia Tbk | D15: 39645
A16: 16 | B16: AEGS | C16: PT Anugerah Spareparts Sejahtera Tbk. | D16: 45180
A17: 17 | B17: AGAR | C17: PT Asia Sejahtera Mina Tbk | D17: 02 Des 2019
A18: 18 | B18: AGII | C18: PT Samator Indo Gas Tbk | D18: 42641
A19: 19 | B19: AGRO | C19: PT Bank Raya Indonesia Tbk | D19: 08 Agt 2003
A20: 20 | B20: AGRS | C20: PT Bank IBK Indonesia Tbk. | D20: 22 Des 2014
A21: 21 | B21: AHAP | C21: Asuransi Harta Aman Pratama Tbk | D21: 33130
A22: 22 | B22: AIMS | C22: PT Artha Mahiya Investama Tbk | D22: 37092
A23: 23 | B23: AISA | C23: PT FKS Food Sejahtera Tbk | D23: 35592
A24: 24 | B24: AKKU | C24: PT Anugerah Kagum Karya Utama Tbk | D24: 38292
A25: 25 | B25: AKPI | C25: Argha Karya Prima Ind. Tbk | D25: 18 Des 1992
A26: 26 | B26: AKRA | C26: PT AKR Corporindo Tbk. | D26: 03 Okt 1994
A27: 27 | B27: AKSI | C27: PT Mineral Sumberdaya Mandiri Tbk | D27: 37085
A28: 28 | B28: ALDO | C28: Alkindo Naratama Tbk | D28: 40736
A29: 29 | B29: ALII | C29: PT Ancara Logistics Indonesia Tbk | D29: 45329
A30: 30 | B30: ALKA | C30: Alakasa Industrindo Tbk | D30: 33066
A31: 31 | B31: ALMI | C31: Alumindo Light Metal Industry Tbk | D31: 35432
A32: 32 | B32: ALTO | C32: Tri Banyan Tirta Tbk | D32: 41100
A33: 33 | B33: AMAG | C33: Asuransi Multi Artha Guna Tbk | D33: 23 Des 2005
A34: 34 | B34: AMAN | C34: PT Makmur Berkah Amanda Tbk. | D34: 43903
A35: 35 | B35: AMAR | C35: PT Bank Amar Indonesia Tbk. | D35: 43839
A36: 36 | B36: AMFG | C36: Asahimas Flat Glass Tbk | D36: 35011
A37: 37 | B37: AMIN | C37: PT Ateliers Mecaniques D Indonesie Tbk. | D37: 10 Des 2015
A38: 38 | B38: AMMN | C38: PT Amman Mineral Internasional Tbk. | D38: 45114
A39: 39 | B39: AMMS | C39: PT Agung Menjangan Mas Tbk | D39: 04 Agt 2022
A40: 40 | B40: AMOR | C40: PT Ashmore Asset Management Indonesia Tbk. | D40: 43844
...

Sheet FIXED ASSET
A1: ='INCOME STATEMENT'!A1 -> Makmur Jaya Sejati Raya
A2: Fixed Asset Schedules
A3: ='[3]BALANCE SHEET'!A3 -> (IDR)
C5: ='BALANCE SHEET'!C4 -> 2019 | D5: =C5+1 -> 2020 | E5: =D5+1 -> 2021
A6: A. Acquisition Costs
A7: Beginning
B8: Land (Tanah Lahan Sawit + Tanah Lahan Sawit (TA)) | C8: =1267580000+3184183925 -> 4451763925 | D8: =C26 -> 7817274315 | E8: =D26 -> 7817274315 | F8: =4633090390+3184183925 -> 7817274315 | H8: Isinya Rumus
B9: Building (Bangunan Mess/Barak + Bangunan Mess/Barak (TA) + Lapangan + Kantor) | C9: =200592860+105000000+131056000+104864091 -> 541512951 | D9: =C27 -> 651512951 | E9: =D27 -> 653687951 | F9: =310592860+105000000+131056000+107039091 -> 653687951
B10: Equipment, Laboratory, & Machinery (Sarana & Prasarana) | C10: 176449500 | D10: =C28 -> 176449500 | E10: =D28 -> 176449500
B11: Vehicle & Heavy Equipment (Alat Berat + Kendaraan) | C11: =350000000+1435472728 -> 1785472728 | D11: =C29 -> 2060472728 | E11: =D29 -> 2207972728 | F11: =625000000+1582972728 -> 2207972728
B12: Office Inventory (Inventaris Tanaman Sawit + Inventaris Tanaman Sawit (TA)) | C12: =1720800000+2000000000 -> 3720800000 | D12: =C30 -> 10145509610 | E12: =D30 -> 10145509610 | F12: =8145509610+2000000000 -> 10145509610
B13: Electrical | C13: 0 | D13: =C31 -> 0 | E13: =D31 -> 0
A14: Total | C14: =SUM(C8:C13) -> 10675999104 | D14: =SUM(D8:D13) -> 20851219104 | E14: =SUM(E8:E13) -> 21000894104
A16: Additions | G16: =$D$5 -> 2020 | H16: =$E$5 -> 2021 | I16: AVERAGE
B17: Land (Tanah Lahan Sawit + Tanah Lahan Sawit (TA)) | C17: 3365510390 | D17: 0 | E17: 0 | G17: =IFERROR((D17-C17)/C17,0) -> -1 | H17: =IFERROR((E17-D17)/D17,0) -> 0 | I17: =AVERAGE(G17:H17) -> -0.5
B18: Building (Bangunan Mess/Barak + Bangunan Mess/Barak (TA) + Lapangan + Kantor) | C18: 110000000 | D18: 2175000 | E18: 0 | G18: =IFERROR((D18-C18)/C18,0) -> -0.98022727 | H18: =IFERROR((E18-D18)/D18,0) -> -1 | I18: =AVERAGE(G18:H18) -> -0.99011364
B19: Equipment, Laboratory, & Machinery (Sarana & Prasarana) | C19: 0 | D19: 0 | E19: 0 | G19: =IFERROR((D19-C19)/C19,0) -> 0 | H19: =IFERROR((E19-D19)/D19,0) -> 0 | I19: =AVERAGE(G19:H19) -> 0
B20: Vehicle & Heavy Equipment (Alat Berat + Kendaraan) | C20: 275000000 | D20: 147500000 | E20: 0 | G20: =IFERROR((D20-C20)/C20,0) -> -0.46363636 | H20: =IFERROR((E20-D20)/D20,0) -> -1 | I20: =AVERAGE(G20:H20) -> -0.73181818
B21: Office Inventory (Inventaris Tanaman Sawit + Inventaris Tanaman Sawit (TA)) | C21: 6424709610 | D21: 0 | E21: 0 | G21: =IFERROR((D21-C21)/C21,0) -> -1 | H21: =IFERROR((E21-D21)/D21,0) -> 0 | I21: =AVERAGE(G21:H21) -> -0.5
B22: Electrical | C22: 0 | D22: 0 | E22: 0 | G22: =IFERROR((D22-C22)/C22,0) -> 0 | H22: =IFERROR((E22-D22)/D22,0) -> 0 | I22: =AVERAGE(G22:H22) -> 0
A23: Total | C23: =SUM(C17:C22) -> 10175220000 | D23: =SUM(D17:D22) -> 149675000 | E23: =SUM(E17:E22) -> 0
A25: Ending
B26: Land (Tanah Lahan Sawit + Tanah Lahan Sawit (TA)) | C26: =+C8+C17 -> 7817274315 | D26: =+D8+D17 -> 7817274315 | E26: =+E8+E17 -> 7817274315
B27: Building (Bangunan Mess/Barak + Bangunan Mess/Barak (TA) + Lapangan + Kantor) | C27: =+C9+C18 -> 651512951 | D27: =+D9+D18 -> 653687951 | E27: =+E9+E18 -> 653687951
B28: Equipment, Laboratory, & Machinery (Sarana & Prasarana) | C28: =+C10+C19 -> 176449500 | D28: =+D10+D19 -> 176449500 | E28: =+E10+E19 -> 176449500
B29: Vehicle & Heavy Equipment (Alat Berat + Kendaraan) | C29: =+C11+C20 -> 2060472728 | D29: =+D11+D20 -> 2207972728 | E29: =+E11+E20 -> 2207972728
B30: Office Inventory (Inventaris Tanaman Sawit + Inventaris Tanaman Sawit (TA)) | C30: =+C12+C21 -> 10145509610 | D30: =+D12+D21 -> 10145509610 | E30: =+E12+E21 -> 10145509610
B31: Electrical | C31: =+C13+C22 -> 0 | D31: =+D13+D22 -> 0 | E31: =+E13+E22 -> 0
A32: Total | C32: =+C14+C23 -> 20851219104 | D32: =+D14+D23 -> 21000894104 | E32: =+E14+E23 -> 21000894104
A34: B. Depreciation
A35: Beginning
B36: Land (Tanah Lahan Sawit + Tanah Lahan Sawit (TA)) | C36: 0 | D36: =C54 -> 0 | E36: =D54 -> 0
B37: Building (Bangunan Mess/Barak + Bangunan Mess/Barak (TA) + Lapangan + Kantor) | C37: 203967215 | D37: =C55 -> 242886427 | E37: =D55 -> 276895183
B38: Equipment, Laboratory, & Machinery (Sarana & Prasarana) | C38: 141871766 | D38: =C56 -> 155035543 | E38: =D56 -> 165897295
B39: Vehicle & Heavy Equipment (Alat Berat + Kendaraan) | C39: 1433114708 | D39: =C57 -> 1637977421 | E39: =D57 -> 1826348345
B40: Office Inventory (Inventaris Tanaman Sawit + Inventaris Tanaman Sawit (TA)) | C40: 754572077 | D40: =C58 -> 851107950 | E40: =D58 -> 1738665546
B41: Electrical | C41: 0 | D41: =C59 -> 0 | E41: =D59 -> 0
A42: Total | B42: =2391654000+141871766 -> 2533525766 | C42: =SUM(C36:C41) -> 2533525766 | D42: =SUM(D36:D41) -> 2887007341 | E42: =SUM(E36:E41) -> 4007806369
A44: Additions | G44: =$D$5 -> 2020 | H44: =$E$5 -> 2021 | I44: AVERAGE
B45: Land (Tanah Lahan Sawit + Tanah Lahan Sawit (TA)) | C45: 0 | D45: 0 | E45: 0 | G45: =IFERROR((D45-C45)/C45,0) -> 0 | H45: =IFERROR((E45-D45)/D45,0) -> 0 | I45: =AVERAGE(G45:H45) -> 0
...

Sheet BALANCE SHEET
A1: =HOME!B4 -> Makmur Jaya Sejati Raya | N1: LEGENDA
A2: Balance Sheet | G2: COMMON SIZE | O2: Komponen Cash Flow Statement, Changes on Working Capital, Current Assets
A3: (IDR) | O3: Komponen Cash Flow Statement, Changes on Working Capital, Current Liabilities
C4: =D4-1 -> 2019 | D4: =E4-1 -> 2020 | E4: =YEAR(HOME!B20) -> 2021 | G4: 2021 | H4: 2022 | I4: 2023 | J4: AVG | L4: Growth | M4: 2021 | N4: 2022 | O4: 2023 | P4: AVG
A5: ASSETS
A7: Current Assets
B8: Cash on Hands (Kas + Kas) | C8: 44887819 | D8: =53472823+97995296 -> 151468119 | E8: =82771246+635077549 -> 717848795 | G8: =C8/C$26 -> 0.0024042069 | H8: =D8/D$26 -> 0.0082273239 | I8: =E8/E$26 -> 0.04154628 | J8: =AVERAGE(G8:I8) -> 0.017392604 | M8: =0 -> 0 | N8: =IFERROR((D8-C8)/C8,0) -> 2.3743702 | O8: =IFERROR((E8-D8)/D8,0) -> 3.7392732 | P8: =AVERAGE(M8:O8) -> 2.0378811
B9: Cash on Bank (Bank Danomon A/C 006600669813 + Deposito Bank Danamon) | C9: 374140018 | D9: 572440850 | E9: 337031731 | G9: =C9/C$26 -> 0.020039067 | H9: =D9/D$26 -> 0.031093383 | I9: =E9/E$26 -> 0.019506078 | J9: =AVERAGE(G9:I9) -> 0.023546176 | M9: =0 -> 0 | N9: =IFERROR((D9-C9)/C9,0) -> 0.5300177 | O9: =IFERROR((E9-D9)/D9,0) -> -0.41123746 | P9: =AVERAGE(M9:O9) -> 0.039593415
B10: Account Receivable (Piutang Dagang) | C10: 248591028 | D10: 675378320 | E10: 191055111 | G10: =C10/C$26 -> 0.01331462 | H10: =D10/D$26 -> 0.036684658 | I10: =E10/E$26 -> 0.011057522 | J10: =AVERAGE(G10:I10) -> 0.020352267 | M10: =0 -> 0 | N10: =IFERROR((D10-C10)/C10,0) -> 1.716825 | O10: =IFERROR((E10-D10)/D10,0) -> -0.71711394 | P10: =AVERAGE(M10:O10) -> 0.33323702
B11: Other Receivable (Piutang Karyawan) | C11: 38700000 | D11: 18000000 | E11: 21000000 | G11: =C11/C$26 -> 0.0020727852 | H11: =D11/D$26 -> 0.00097770958 | I11: =E11/E$26 -> 0.0012153978 | J11: =AVERAGE(G11:I11) -> 0.0014219642 | M11: =0 -> 0 | N11: =IFERROR((D11-C11)/C11,0) -> -0.53488372 | O11: =IFERROR((E11-D11)/D11,0) -> 0.16666667 | P11: =AVERAGE(M11:O11) -> -0.12273902
B12: Inventory | C12: 0 | D12: 0 | E12: 0 | G12: =C12/C$26 -> 0 | H12: =D12/D$26 -> 0 | I12: =E12/E$26 -> 0 | J12: =AVERAGE(G12:I12) -> 0 | M12: =0 -> 0 | N12: =IFERROR((D12-C12)/C12,0) -> 0 | O12: =IFERROR((E12-D12)/D12,0) -> 0 | P12: =AVERAGE(M12:O12) -> 0
B13: Others | C13: 0 | D13: 0 | E13: 0 | G13: =C13/C$26 -> 0 | H13: =D13/D$26 -> 0 | I13: =E13/E$26 -> 0 | J13: =AVERAGE(G13:I13) -> 0 | M13: =0 -> 0 | N13: =IFERROR((D13-C13)/C13,0) -> 0 | O13: =IFERROR((E13-D13)/D13,0) -> 0 | P13: =AVERAGE(M13:O13) -> 0
A15: Current Assets | C15: =SUM(C8:C13) -> 706318865 | D15: =SUM(D8:D13) -> 1417287289 | E15: =SUM(E8:E13) -> 1266935637
A17: Non Current Assets
A18: Fixed Asset
B19: Beginning | C19: ='FIXED ASSET'!C32 -> 20851219104 | D19: ='FIXED ASSET'!D32 -> 21000894104 | E19: ='FIXED ASSET'!E32 -> 21000894104 | G19: =C19/C$26 -> 1.1167984 | H19: =D19/D$26 -> 1.1407097 | I19: =E19/E$26 -> 1.2154496 | J19: =AVERAGE(G19:I19) -> 1.1576526 | M19: =0 -> 0 | N19: =IFERROR((D19-C19)/C19,0) -> 0.0071782374 | O19: =IFERROR((E19-D19)/D19,0) -> 0 | P19: =AVERAGE(M19:O19) -> 0.0023927458
B20: Accumulated Depreciations | C20: ='FIXED ASSET'!C60*-1 -> -2887007341 | D20: ='FIXED ASSET'!D60*-1 -> -4007806369 | E20: ='FIXED ASSET'!E60*-1 -> -4989536710 | G20: =C20/C$26 -> -0.1546291 | H20: =D20/D$26 -> -0.21769282 | I20: =E20/E$26 -> -0.28877486 | J20: =AVERAGE(G20:I20) -> -0.22036559 | M20: =0 -> 0 | N20: =IFERROR((D20-C20)/C20,0) -> 0.38822175 | O20: =IFERROR((E20-D20)/D20,0) -> 0.24495453 | P20: =AVERAGE(M20:O20) -> 0.21105876
B21: Fixed Assets, Net | C21: =C19+C20 -> 17964211763 | D21: =D19+D20 -> 16993087735 | E21: =E19+E20 -> 16011357394 | M21: =0 -> 0 | N21: =IFERROR((D21-C21)/C21,0) -> -0.054058817 | O21: =IFERROR((E21-D21)/D21,0) -> -0.057772334 | P21: =AVERAGE(M21:O21) -> -0.03727705
A22: Non Current Assets | C22: 0 | D22: 0 | E22: 0 | M22: =0 -> 0 | N22: =IFERROR((D22-C22)/C22,0) -> 0 | O22: =IFERROR((E22-D22)/D22,0) -> 0 | P22: =AVERAGE(M22:O22) -> 0
A23: Intangible Assets | C23: 0 | D23: 0 | E23: 0 | M23: =0 -> 0 | N23: =IFERROR((D23-C23)/C23,0) -> 0 | O23: =IFERROR((E23-D23)/D23,0) -> 0 | P23: =AVERAGE(M23:O23) -> 0
A24: Total Non Current Asset | C24: =C21+C22+C23 -> 17964211763 | D24: =D21+D22+D23 -> 16993087735 | E24: =E21+E22+E23 -> 16011357394 | M24: =0 -> 0 | N24: =IFERROR((D24-C24)/C24,0) -> -0.054058817 | O24: =IFERROR((E24-D24)/D24,0) -> -0.057772334 | P24: =AVERAGE(M24:O24) -> -0.03727705
A26: ASSETS | C26: =+C15+C24 -> 18670530628 | D26: =+D15+D24 -> 18410375024 | E26: =+E15+E24 -> 17278293031
A28: LIABILITIES & EQUITY
A29: Current Liabilities
B30: Bank Loan-Short Term | C30: 0 | D30: 0 | E30: 0 | G30: =C30/C$50 -> 0 | H30: =D30/D$50 -> 0 | I30: =E30/E$50 -> 0 | J30: =AVERAGE(G30:I30) -> 0 | M30: =0 -> 0 | N30: =IFERROR((D30-C30)/C30,0) -> 0 | O30: =IFERROR((E30-D30)/D30,0) -> 0 | P30: =AVERAGE(M30:O30) -> 0
B31: Account Payables (Hutang Dagang) | C31: 1349091893 | D31: 722586680 | E31: 1823364600 | G31: =C31/C$50 -> 0.072956728 | H31: =D31/D$50 -> 0.039169761 | I31: =E31/E$50 -> 0.10482686 | J31: =AVERAGE(G31:I31) -> 0.072317782 | M31: =0 -> 0 | N31: =IFERROR((D31-C31)/C31,0) -> -0.46439032 | O31: =IFERROR((E31-D31)/D31,0) -> 1.5233853 | P31: =AVERAGE(M31:O31) -> 0.35299832
B32: Tax Payable (Hutang PPh Pasal 29 + Hutang PPh Pasal 25 + Hutang PPh Pasal 21 + Hutang PPN + PPN dan PPh 29) | C32: =20499268+7791190+71113530 -> 99403988 | D32: =28927903+9457631+2401280+70425650+139134936 -> 250347400 | E32: =263030563+11451679+81022+102761900+301193090 -> 678518254 | G32: =C32/C$50 -> 0.0053756084 | H32: =D32/D$50 -> 0.013570756 | I32: =E32/E$50 -> 0.03900862 | J32: =AVERAGE(G32:I32) -> 0.019318328 | M32: =0 -> 0 | N32: =IFERROR((D32-C32)/C32,0) -> 1.5184845 | O32: =IFERROR((E32-D32)/D32,0) -> 1.7103068 | P32: =AVERAGE(M32:O32) -> 1.0762637
B33: Others (Hutang Gaji Karyawan) | C33: 397739810 | D33: 295472920 | E33: 1075354928 | G33: =C33/C$50 -> 0.021509132 | H33: =D33/D$50 -> 0.016016907 | I33: =E33/E$50 -> 0.061823114 | J33: =AVERAGE(G33:I33) -> 0.033116384 | M33: =0 -> 0 | N33: =IFERROR((D33-C33)/C33,0) -> -0.25712008 | O33: =IFERROR((E33-D33)/D33,0) -> 2.6394365 | P33: =AVERAGE(M33:O33) -> 0.79410547
A34: Current Liabilities | C34: =SUM(C30:C33) -> 1846235691 | D34: =SUM(D30:D33) -> 1268407000 | E34: =SUM(E30:E33) -> 3577237782
A36: Non Current Liabilities
B37: Bank Loan-Long Term | C37: 0 | D37: 0 | E37: 0 | G37: =C37/C$50 -> 0 | H37: =D37/D$50 -> 0 | I37: =E37/E$50 -> 0 | J37: =AVERAGE(G37:I37) -> 0 | M37: =0 -> 0 | N37: =IFERROR((D37-C37)/C37,0) -> 0 | O37: =IFERROR((E37-D37)/D37,0) -> 0 | P37: =AVERAGE(M37:O37) -> 0
B38: Related Party acc. Payable & Employee Benefits | C38: 0 | D38: 0 | E38: 0 | G38: =C38/C$50 -> 0 | H38: =D38/D$50 -> 0 | I38: =E38/E$50 -> 0 | J38: =AVERAGE(G38:I38) -> 0 | M38: =0 -> 0 | N38: =IFERROR((D38-C38)/C38,0) -> 0 | O38: =IFERROR((E38-D38)/D38,0) -> 0 | P38: =AVERAGE(M38:O38) -> 0
A39: Non Current Liabilities | C39: =+C37+C38 -> 0 | D39: =+D37+D38 -> 0 | E39: =+E37+E38 -> 0 | G39: =C39/C$50 -> 0 | H39: =D39/D$50 -> 0 | I39: =E39/E$50 -> 0 | J39: =AVERAGE(G39:I39) -> 0
A40: LIABILITIES | C40: =+C34+C39 -> 1846235691 | D40: =+D34+D39 -> 1268407000 | E40: =+E34+E39 -> 3577237782
A41: Shareholders' Equity
A42: Paid Up Capital (Modal Disetor) | C42: 5280000000 | D42: 5280000000 | E42: 5280000000 | G42: =C42/C$50 -> 0.28553394 | H42: =D42/D$50 -> 0.28621665 | I42: =E42/E$50 -> 0.30355191 | J42: =AVERAGE(G42:I42) -> 0.2917675 | M42: =0 -> 0 | N42: =IFERROR((D42-C42)/C42,0) -> 0 | O42: =IFERROR((E42-D42)/D42,0) -> 0 | P42: =AVERAGE(M42:O42) -> 0
A43: Addition (Uang Muka Setoran Modal) | C43: 3550000000 | D43: 3150000000 | E43: 0
A44: Retained Earnings
B45: Surplus (Laba di Tahan (TA) + Laba Ditahan Tahun Lalu - Deviden) | C45: =5289183925+2085507326 -> 7374691251 | D45: =5289183925+2705111011 -> 7994294936 | E45: =5289183925+3909531302-2500000000 -> 6698715227 | G45: =C45/C$50 -> 0.39881149 | H45: =D45/D$50 -> 0.43335233 | I45: =E45/E$50 -> 0.38511511 | J45: =AVERAGE(G45:I45) -> 0.40575965 | M45: =0 -> 0 | N45: =IFERROR((D45-C45)/C45,0) -> 0.084017576 | O45: =IFERROR((E45-D45)/D45,0) -> -0.16206304 | P45: =AVERAGE(M45:O45) -> -0.026015153
B46: Current Profit - Commercial NPAT (Laba Bersih Komersial) | C46: ='INCOME STATEMENT'!C35 -> 440745074 | D46: ='INCOME STATEMENT'!D35 -> 754862153 | E46: ='INCOME STATEMENT'!E35 -> 1838106527 | G46: =C46/C$50 -> 0.023834788 | H46: =D46/D$50 -> 0.04091934 | I46: =E46/E$50 -> 0.10567438 | J46: =AVERAGE(G46:I46) -> 0.056809504 | M46: =0 -> 0 | N46: =IFERROR((D46-C46)/C46,0) -> 0.71269561 | O46: =IFERROR((E46-D46)/D46,0) -> 1.4350228 | P46: =AVERAGE(M46:O46) -> 0.71590612
...

Sheet INCOME STATEMENT
A1: ='BALANCE SHEET'!A1 -> Makmur Jaya Sejati Raya
A2: Income Statement
A3: ='[3]BALANCE SHEET'!A3 -> (IDR) | G3: COMMON SIZE | L3: HORIZONTAL
C5: =D5-1 -> 2019 | D5: =E5-1 -> 2020 | E5: =YEAR(HOME!B20) -> 2021 | G5: =C5 -> 2019 | H5: =D5 -> 2020 | I5: =E5 -> 2021 | J5: AVG | L5: 2021 | M5: 2022 | N5: 2023 | O5: AVG
A6: Revenue (Penjualan) | C6: 9335637236 | D6: 11406787320 | E6: =16663916100 -> 16663916100 | G6: =IFERROR((C6-0)/0,0) -> 0 | H6: =(D6-C6)/C6 -> 0.22185417 | I6: =(E6-D6)/D6 -> 0.46087725 | J6: =AVERAGE(G6:I6) -> 0.22757714 | L6: =IFERROR((C6-0)/0,0) -> 0 | M6: =(D6-C6)/C6 -> 0.22185417 | N6: =(E6-D6)/D6 -> 0.46087725 | O6: =AVERAGE(L6:N6) -> 0.22757714
A7: Cost of Good Sold (Pupuk + Obat-Obatan + Ongkos Angkut Pembelian TBS + Langsir & Muat TBS + Gaji Pegawai Bag. Lapangan + Keperluan Lapangan + Bibit Sawit) | C7: =(1341236655+237790000+532433990+60489260+4531901900+176756281)*-1 -> -6880608086 | D7: =(1118290360+389785500+47250000+678881440+154953960+4984022900+192568750)*-1 -> -7565752910 | E7: =(1868593447+567317727+806095500+470963990+6699039850+367647700)*-1 -> -10779658214 | G7: =C7/C$6 -> -0.73702608 | H7: =D7/D$6 -> -0.66326764 | I7: =E7/E$6 -> -0.64688625 | J7: =AVERAGE(G7:I7) -> -0.68239332 | L7: =IFERROR((C7-0)/0,0) -> 0 | M7: =(D7-C7)/C7 -> 0.099576202 | N7: =(E7-D7)/D7 -> 0.42479649 | O7: =AVERAGE(L7:N7) -> 0.1747909
A8: Gross Profit | C8: =SUM(C6:C7) -> 2455029150 | D8: =SUM(D6:D7) -> 3841034410 | E8: =SUM(E6:E7) -> 5884257886 | G8: =C8/C$6 -> 0.26297392 | H8: =D8/D$6 -> 0.33673236 | I8: =E8/E$6 -> 0.35311375 | J8: =AVERAGE(G8:I8) -> 0.31760668
B9: Gross Profit Margin | C9: =+C8/C6 -> 0.26297392 | D9: =+D8/D6 -> 0.33673236 | E9: =+E8/E6 -> 0.35311375 | I9: =I8-H8 -> 0.016381389
A11: Operating Expenses:
B12: Others | C12: 0 | D12: 0 | E12: 0 | G12: =C12/C$6 -> 0 | H12: =D12/D$6 -> 0 | I12: =E12/E$6 -> 0 | J12: =AVERAGE(G12:I12) -> 0 | L12: =IFERROR((C12-0)/0,0) -> 0 | M12: =IFERROR((D12-C12)/C12,0) -> 0 | N12: =IFERROR((E12-D12)/D12,0) -> 0 | O12: =AVERAGE(L12:N12) -> 0
B13: General & Administrative Overheads (Iuran & Retribusi + BBM + STNK & Pajak Kendaraan + Spare Parts Kendaraan + Perjalanan Dinas + Pem. & Perawatan Sarana & Prasarana + Gaji Pegawai Bag. Administrasi + Adm. Bank + Rek. Listrik + Keperluan Kantor + STP + PBB + Pemeliharaan Mess + Notaris) | C13: =(28989940+226329500+10176400+336574200+171636900+55010000+507006500+1505306+4000000+17133467+25364440+36857132)*-1 -> -1420583785 | D13: =(39888220+388515583+12543000+475888200+19685000+331373500+445539100+1477600+22156200+14335851+58476654)*-1 -> -1809878908 | E13: =(10290500+543625269+10767100+809649273+146537000+507940000+449519500+1418500+24268976+37800600+34972298+64306088)*-1 -> -2641095104 | G13: =C13/C$6 -> -0.15216784 | H13: =D13/D$6 -> -0.15866684 | I13: =E13/E$6 -> -0.15849186 | J13: =AVERAGE(G13:I13) -> -0.15644218 | L13: =IFERROR((C13-0)/0,0) -> 0 | M13: =(D13-C13)/C13 -> 0.27403883 | N13: =(E13-D13)/D13 -> 0.45926619 | O13: =AVERAGE(L13:N13) -> 0.24443501
A15: Operating Expenses | C15: =C12+C13 -> -1420583785 | D15: =D12+D13 -> -1809878908 | E15: =E12+E13 -> -2641095104 | G15: =C15/C$6 -> -0.15216784 | H15: =D15/D$6 -> -0.15866684 | I15: =E15/E$6 -> -0.15849186 | J15: =AVERAGE(G15:I15) -> -0.15644218 | L15: =IFERROR((C15-0)/0,0) -> 0 | M15: =(D15-C15)/C15 -> 0.27403883 | N15: =(E15-D15)/D15 -> 0.45926619 | O15: =AVERAGE(L15:N15) -> 0.24443501
A16: (Exclude Depreciation)
A18: EBITDA | C18: =C8+C15 -> 1034445365 | D18: =D8+D15 -> 2031155502 | E18: =E8+E15 -> 3243162782 | G18: =C18/C$6 -> 0.11080608 | H18: =D18/D$6 -> 0.17806552 | I18: =E18/E$6 -> 0.19462189 | J18: =AVERAGE(G18:I18) -> 0.16116449 | L18: =IFERROR((C18-0)/0,0) -> 0 | M18: =(D18-C18)/C18 -> 0.96352129 | N18: =(E18-D18)/D18 -> 0.59670827 | O18: =AVERAGE(L18:N18) -> 0.52007652
B19: EBITDA margin | C19: =C18/C6 -> 0.11080608 | D19: =D18/D6 -> 0.17806552 | E19: =E18/E6 -> 0.19462189
A21: Depreciation | C21: ='FIXED ASSET'!C51*-1 -> -353481575 | D21: ='FIXED ASSET'!D51*-1 -> -1120799028 | E21: ='FIXED ASSET'!E51*-1 -> -981730341
A22: EBIT | C22: =+C18+C21 -> 680963790 | D22: =+D18+D21 -> 910356474 | E22: =+E18+E21 -> 2261432441 | G22: =C22/C$6 -> 0.0729424 | H22: =D22/D$6 -> 0.079808315 | I22: =E22/E$6 -> 0.13570834 | J22: =AVERAGE(G22:I22) -> 0.096153019 | L22: =IFERROR((C22-0)/0,0) -> 0 | M22: =(D22-C22)/C22 -> 0.33686473 | N22: =(E22-D22)/D22 -> 1.4841175 | O22: =AVERAGE(L22:N22) -> 0.60699407
B23: EBIT margin | C23: =+C22/C6 -> 0.0729424 | D23: =+D22/D6 -> 0.079808315 | E23: =+E22/E6 -> 0.13570834 | G23: =C23/C$6 -> 7.8133285e-12 | H23: =D23/D$6 -> 6.9965638e-12 | I23: =E23/E$6 -> 8.1438446e-12 | J23: =AVERAGE(G23:I23) -> 7.6512456e-12
A25: Other Incomes/(Charges):
B26: Interest Income (Pendapatan Jasa Giro + Pendapatan Bagi Hasil (Bank) + Pendapatan Bunga Deposito) | C26: =7222836+74171233 -> 81394069 | D26: =6803933+5000000 -> 11803933 | E26: =(2443706+2266459+9247176) -> 13957341 | G26: =C26/C$6 -> 0.0087186409 | H26: =D26/D$6 -> 0.0010348166 | I26: =E26/E$6 -> 0.00083757869 | J26: =AVERAGE(G26:I26) -> 0.0035303454
B27: Interest Expense (Beban Jasa Giro + Beban Lain-Lain) | C27: =(1444567+14834247)*-1 -> -16278814 | D27: =(1360787+341)*-1 -> -1361128 | E27: =(488741+453292)*-1 -> -942033 | G27: =C27/C$6 -> -0.0017437282 | H27: =D27/D$6 -> -0.00011932615 | I27: =E27/E$6 -> -5.653131e-05 | J27: =AVERAGE(G27:I27) -> -0.00063986189 | L27: =IFERROR((C27-0)/0,0) -> 0 | M27: =(D27-C27)/C27 -> -0.91638654 | N27: =(E27-D27)/D27 -> -0.30790271 | O27: =AVERAGE(L27:N27) -> -0.40809642
A28: Other Incomes/(Charges) | C28: =+C26+C27 -> 65115255 | D28: =+D26+D27 -> 10442805 | E28: =+E26+E27 -> 13015308 | G28: =C28/C$6 -> 0.0069749127 | H28: =D28/D$6 -> 0.00091549046 | I28: =E28/E$6 -> 0.00078104738 | J28: =AVERAGE(G28:I28) -> 0.0028904835 | L28: =IFERROR((C28-0)/0,0) -> 0 | M28: =(D28-C28)/C28 -> -0.83962583 | N28: =(E28-D28)/D28 -> 0.24634215 | O28: =AVERAGE(L28:N28) -> -0.19776123
A30: Non Operating Income (Pendapatan Lain-Lain - Beban Lain-Lain) | C30: 0 | D30: 0 | E30: =(12125-225000) -> -212875 | G30: =C30/C$6 -> 0 | H30: =D30/D$6 -> 0 | I30: =E30/E$6 -> -1.2774608e-05 | J30: =AVERAGE(G30:I30) -> -4.2582027e-06 | L30: =IFERROR((C30-0)/0,0) -> 0 | M30: =IFERROR((D30-C30)/C30,0) -> 0 | N30: =IFERROR((E30-D30)/D30,0) -> 0 | O30: =AVERAGE(L30:N30) -> 0
A32: Profit Before Tax | C32: =+C22+C28+C30 -> 746079045 | D32: =+D22+D28+D30 -> 920799279 | E32: =+E22+E28+E30 -> 2274234874 | G32: =C32/C$6 -> 0.079917313 | H32: =D32/D$6 -> 0.080723805 | I32: =E32/E$6 -> 0.13647662 | J32: =AVERAGE(G32:I32) -> 0.099039245 | L32: =IFERROR((C32-0)/0,0) -> 0 | M32: =(D32-C32)/C32 -> 0.23418462 | N32: =(E32-D32)/D32 -> 1.4698487 | O32: =AVERAGE(L32:N32) -> 0.56801109
A33: Corporate Tax | C33: -305333971 | D33: -165937126 | E33: -436128347 | I33: =(E33-D33)/D33 -> 1.6282747
A35: Net Profit After Tax | C35: =+C32+C33 -> 440745074 | D35: =+D32+D33 -> 754862153 | E35: =+E32+E33 -> 1838106527 | G35: =C35/C$6 -> 0.047211033 | H35: =D35/D$6 -> 0.066176578 | I35: =E35/E$6 -> 0.1103046 | J35: =AVERAGE(G35:I35) -> 0.074564069 | L35: =IFERROR((C35-0)/0,0) -> 0 | M35: =(D35-C35)/C35 -> 0.71269561 | N35: =(E35-D35)/D35 -> 1.4350228 | O35: =AVERAGE(L35:N35) -> 0.71590612
B36: Net Profit Margin | C36: =+C35/C6 -> 0.047211033 | D36: =+D35/D6 -> 0.066176578 | E36: =+E35/E6 -> 0.1103046 | H36: =I35-H35 -> 0.044128017

Sheet ACC PAYABLES
A1: =HOME!B4 -> Makmur Jaya Sejati Raya
A2: Bank Loan Schedules
A3: ='BALANCE SHEET'!A3 -> (IDR)
C5: ='FIXED ASSET'!C5 -> 2019 | D5: ='FIXED ASSET'!D5 -> 2020 | E5: ='FIXED ASSET'!E5 -> 2021
A7: Bank Loan-SHORT TERM
A8: Principal | C8: 0.13 | D8: 0.13 | E8: 0.13
A9: Beginning | C9: =0 -> 0 | D9: =C12 -> 0 | E9: =D12 -> 0
B10: Addition | C10: =('BALANCE SHEET'!C30-0) -> 0 | D10: =('BALANCE SHEET'!D30-'BALANCE SHEET'!C30) -> 0 | E10: =('BALANCE SHEET'!E30-'BALANCE SHEET'!D30) -> 0
B11: Repayment | C11: 0 | D11: 0 | E11: 0
A12: Ending | C12: =SUM(C9:C11) -> 0 | D12: =SUM(D9:D11) -> 0 | E12: =SUM(E9:E11) -> 0
A14: Interest Payable | C14: 0 | D14: 0 | E14: 0
A16: Bank Loan-LONG TERM
A17: Principal | C17: 0.13 | D17: 0.13 | E17: 0.13
A18: Beginning | C18: 0 | D18: =C21 -> 0 | E18: =D21 -> 0
B19: Addition | C19: 0 | D19: 0 | E19: 0
B20: Repayment | C20: 0 | D20: 0 | E20: 0
A21: Ending | C21: =SUM(C18:C20) -> 0 | D21: =SUM(D18:D20) -> 0 | E21: =SUM(E18:E20) -> 0
A23: Interest Payable | C23: 0 | D23: 0 | E23: 0

Sheet CASH FLOW STATEMENT
A1: =HOME!B4 -> Makmur Jaya Sejati Raya
A2: Cash Flow Statement
A3: ='BALANCE SHEET'!A3 -> (IDR)
C4: ='INCOME STATEMENT'!C5 -> 2019 | D4: ='INCOME STATEMENT'!D5 -> 2020 | E4: ='INCOME STATEMENT'!E5 -> 2021 | I4: LEGENDA
A5: EBITDA | C5: ='INCOME STATEMENT'!C18 -> 1034445365 | D5: ='INCOME STATEMENT'!D18 -> 2031155502 | E5: ='INCOME STATEMENT'!E18 -> 3243162782 | J5: ="Angkanya didapat dari saldo "&C4&" - "&C4-1&", karena "&C4-1&" ada LK-nya sehingga diisi sekalian di Balance Sheet biar otomatis nyambung." -> Angkanya didapat dari saldo 2019 - 2018, karena 2018 ada LK-nya sehingga diisi sekalian di Balance Sheet biar otomatis nyambung.
A6: Corporate Tax | C6: ='INCOME STATEMENT'!C33 -> -305333971 | D6: ='INCOME STATEMENT'!D33 -> -165937126 | E6: ='INCOME STATEMENT'!E33 -> -436128347
A7: Changes in Working Capital
B8: Operating Current Assets (AR + Inventory) | C8: =('BALANCE SHEET'!C10+'BALANCE SHEET'!C12)*-1 -> -248591028 | D8: =(('BALANCE SHEET'!D10+'BALANCE SHEET'!D12)-('BALANCE SHEET'!C10+'BALANCE SHEET'!C12))*-1 -> -426787292 | E8: =(('BALANCE SHEET'!E10+'BALANCE SHEET'!E12)-('BALANCE SHEET'!D10+'BALANCE SHEET'!D12))*-1 -> 484323209
B9: Operating Current Liabilities (AP + Other Payable) | C9: =('BALANCE SHEET'!C31+'BALANCE SHEET'!C33)-(0+0) -> 1746831703 | D9: =('BALANCE SHEET'!D31+'BALANCE SHEET'!D33)-('BALANCE SHEET'!C31+'BALANCE SHEET'!C33) -> -728772103 | E9: =('BALANCE SHEET'!E31+'BALANCE SHEET'!E33)-('BALANCE SHEET'!D31+'BALANCE SHEET'!D33) -> 1880659928
A10: Working Capital | C10: =+C8+C9 -> 1498240675 | D10: =+D8+D9 -> -1155559395 | E10: =+E8+E9 -> 2364983137
A11: Cash Flow from Operations | C11: =SUM(C5:C9) -> 2227352069 | D11: =SUM(D5:D9) -> 709658981 | E11: =SUM(E5:E9) -> 5172017572
A13: Cash Flow from Non Operations | C13: ='INCOME STATEMENT'!C30 -> 0 | D13: ='INCOME STATEMENT'!D30 -> 0 | E13: ='INCOME STATEMENT'!E30 -> -212875
A17: Cash Flow from Investment (Capital Expenditure) | C17: ='FIXED ASSET'!C23*-1 -> -10175220000 | D17: ='FIXED ASSET'!D23*-1 -> -149675000 | E17: ='FIXED ASSET'!E23*-1 -> 0
A19: Cash Flow before Financing | C19: =C11+C13+C17 -> -7947867931 | D19: =D11+D13+D17 -> 559983981 | E19: =E11+E13+E17 -> 5171804697
A21: Financing
B22: Equity Injection | C22: =('BALANCE SHEET'!C42+'BALANCE SHEET'!C43)-0 -> 8830000000 | D22: =('BALANCE SHEET'!D42+'BALANCE SHEET'!D43)-('BALANCE SHEET'!C42+'BALANCE SHEET'!C43) -> -400000000 | E22: =('BALANCE SHEET'!E42+'BALANCE SHEET'!E43)-('BALANCE SHEET'!D42+'BALANCE SHEET'!D43) -> -3150000000
B23: New Loan | C23: ='ACC PAYABLES'!C10+'ACC PAYABLES'!C19 -> 0 | D23: ='ACC PAYABLES'!D10+'ACC PAYABLES'!D19 -> 0 | E23: ='ACC PAYABLES'!E10+'ACC PAYABLES'!E19 -> 0
B24: Interenst Payment | C24: ='INCOME STATEMENT'!C27 -> -16278814 | D24: ='INCOME STATEMENT'!D27 -> -1361128 | E24: ='INCOME STATEMENT'!E27 -> -942033
B25: Interest Income | C25: ='INCOME STATEMENT'!C26 -> 81394069 | D25: ='INCOME STATEMENT'!D26 -> 11803933 | E25: ='INCOME STATEMENT'!E26 -> 13957341
B26: Principal Repayment | C26: ='ACC PAYABLES'!C20 -> 0 | D26: ='ACC PAYABLES'!D20 -> 0 | E26: ='ACC PAYABLES'!E20 -> 0
A28: Cash Flow from Financing | C28: =SUM(C22:C26) -> 8895115255 | D28: =SUM(D22:D26) -> -389557195 | E28: =SUM(E22:E26) -> -3136984692
A30: Net Cash Flow | C30: =+C11+C13+C17+C28 -> 947247324 | D30: =+D11+D13+D17+D28 -> 170426786 | E30: =+E11+E13+E17+E28 -> 2034820005
A32: Cash-Beginning Balance | C32: =259004307+250716909+3500000000 -> 4009721216 | D32: =C33 -> 419027837 | E32: =D33 -> 723908969
A33: Cash-Ending Balance | C33: ='BALANCE SHEET'!C8+'BALANCE SHEET'!C9 -> 419027837 | D33: ='BALANCE SHEET'!D8+'BALANCE SHEET'!D9 -> 723908969 | E33: ='BALANCE SHEET'!E8+'BALANCE SHEET'!E9 -> 1054880526
A35: Cash Ending in Bank | C35: ='BALANCE SHEET'!C9 -> 374140018 | D35: ='BALANCE SHEET'!D9 -> 572440850 | E35: ='BALANCE SHEET'!E9 -> 337031731
A36: Cash Ending in Cash on Hand | C36: ='BALANCE SHEET'!C8 -> 44887819 | D36: ='BALANCE SHEET'!D8 -> 151468119 | E36: ='BALANCE SHEET'!E8 -> 717848795

Sheet FINANCIAL RATIO
A1: =HOME!B4 -> Makmur Jaya Sejati Raya
A2: Financial Ratios
B4: Ratio | C4: Formula | D4: =ROIC!B5 -> 2019 | E4: =ROIC!C5 -> 2020 | F4: =ROIC!D5 -> 2021 | G4: Average
A5: Profitability Indicator Ratio | B5: Profitability Indicator Ratio | C5: Formula | D5: Column3 | E5: Column4 | F5: Column5 | G5: Column6
B6: Gross Profit Margin | C6: GP/Sales | D6: ='INCOME STATEMENT'!C9 -> 0.26297392 | E6: ='INCOME STATEMENT'!D9 -> 0.33673236 | F6: ='INCOME STATEMENT'!E9 -> 0.35311375 | G6: =AVERAGE(D6:F6) -> 0.31760668
B7: EBITDA Margin | C7: EBITDA/Sales | D7: ='INCOME STATEMENT'!C19 -> 0.11080608 | E7: ='INCOME STATEMENT'!D19 -> 0.17806552 | F7: ='INCOME STATEMENT'!E19 -> 0.19462189 | G7: =AVERAGE(D7:F7) -> 0.16116449
B8: EBIT Margin | C8: EBIT/Sales | D8: ='INCOME STATEMENT'!C23 -> 0.0729424 | E8: ='INCOME STATEMENT'!D23 -> 0.079808315 | F8: ='INCOME STATEMENT'!E23 -> 0.13570834 | G8: =AVERAGE(D8:F8) -> 0.096153019
B9: Net Profit Margin | C9: Net Profit/Sales | D9: ='INCOME STATEMENT'!C36 -> 0.047211033 | E9: ='INCOME STATEMENT'!D36 -> 0.066176578 | F9: ='INCOME STATEMENT'!E36 -> 0.1103046 | G9: =AVERAGE(D9:F9) -> 0.074564069
B10: Return On Asset | C10: Net Profit/Asset | D10: ='INCOME STATEMENT'!C35/'BALANCE SHEET'!C26 -> 0.023606457 | E10: ='INCOME STATEMENT'!D35/'BALANCE SHEET'!D26 -> 0.041001998 | F10: ='INCOME STATEMENT'!E35/'BALANCE SHEET'!E26 -> 0.10638241 | G10: =AVERAGE(D10:F10) -> 0.056996956
B11: Return On Equity | C11: Net Profit/Equity | D11: ='INCOME STATEMENT'!C35/'BALANCE SHEET'!C48 -> 0.026478433 | E11: ='INCOME STATEMENT'!D35/'BALANCE SHEET'!D48 -> 0.043940582 | F11: ='INCOME STATEMENT'!E35/'BALANCE SHEET'!E48 -> 0.13303396 | G11: =AVERAGE(D11:F11) -> 0.067817659
A13: Liquidity Measurement Ratio | B13: Liquidity Measurement Ratio | C13: Formula | D13: Column3 | E13: Column4 | F13: Column5 | G13: Column6
B14: Current Ratio | C14: CA/CL | D14: ='BALANCE SHEET'!C15/'BALANCE SHEET'!C34 -> 0.38257242 | E14: ='BALANCE SHEET'!D15/'BALANCE SHEET'!D34 -> 1.1173758 | F14: ='BALANCE SHEET'!E15/'BALANCE SHEET'!E34 -> 0.3541659 | G14: =AVERAGE(D14:F14) -> 0.61803804
B15: Quick Ratio | C15: (Cash+A/R)/CL | D15: =('BALANCE SHEET'!C8+'BALANCE SHEET'!C9+'BALANCE SHEET'!C10)/'BALANCE SHEET'!C34 -> 0.36161085 | E15: =('BALANCE SHEET'!D8+'BALANCE SHEET'!D9+'BALANCE SHEET'!D10)/'BALANCE SHEET'!D34 -> 1.1031848 | F15: =('BALANCE SHEET'!E8+'BALANCE SHEET'!E9+'BALANCE SHEET'!E10)/'BALANCE SHEET'!E34 -> 0.34829545 | G15: =AVERAGE(D15:F15) -> 0.60436369
B16: Cash Ratio | C16: Cash/CL | D16: =('BALANCE SHEET'!C8+'BALANCE SHEET'!C9)/'BALANCE SHEET'!C34 -> 0.22696335 | E16: =('BALANCE SHEET'!D8+'BALANCE SHEET'!D9)/'BALANCE SHEET'!D34 -> 0.57072294 | F16: =('BALANCE SHEET'!E8+'BALANCE SHEET'!E9)/'BALANCE SHEET'!E34 -> 0.29488689 | G16: =AVERAGE(D16:F16) -> 0.36419106
A18: Leverage Ratio | B18: Leverage Ratio | C18: Formula | D18: Column3 | E18: Column4 | F18: Column5 | G18: Column6
B19: Debt to Assets Ratio | C19: Liabilities/Asset | D19: =('BALANCE SHEET'!C34+'BALANCE SHEET'!C39)/'BALANCE SHEET'!C26 -> 0.098885014 | E19: =('BALANCE SHEET'!D34+'BALANCE SHEET'!D39)/'BALANCE SHEET'!D26 -> 0.068896315 | F19: =('BALANCE SHEET'!E34+'BALANCE SHEET'!E39)/'BALANCE SHEET'!E26 -> 0.20703653 | G19: =AVERAGE(D19:F19) -> 0.12493929
B20: Debt to Equity Ratio | C20: Liabilities/Equity | D20: =('BALANCE SHEET'!C34+'BALANCE SHEET'!C39)/'BALANCE SHEET'!C48 -> 0.11091543 | E20: =('BALANCE SHEET'!D34+'BALANCE SHEET'!D39)/'BALANCE SHEET'!D48 -> 0.073834065 | F20: =('BALANCE SHEET'!E34+'BALANCE SHEET'!E39)/'BALANCE SHEET'!E48 -> 0.25890453 | G20: =AVERAGE(D20:F20) -> 0.14788468
B21: Capitalization Ratio | C21: LTD/(LTD+Equity) | D21: ='BALANCE SHEET'!C37/('BALANCE SHEET'!C37+'BALANCE SHEET'!C48) -> 0 | E21: ='BALANCE SHEET'!D37/('BALANCE SHEET'!D37+'BALANCE SHEET'!D48) -> 0 | F21: ='BALANCE SHEET'!E37/('BALANCE SHEET'!E37+'BALANCE SHEET'!E48) -> 0 | G21: =AVERAGE(D21:F21) -> 0
B22: Interest Coverage | C22: EBIT/Interest Expense | D22: =IFERROR(ABS('INCOME STATEMENT'!C22/'INCOME STATEMENT'!C27),0) -> 41.83129 | E22: =IFERROR(ABS('INCOME STATEMENT'!D22/'INCOME STATEMENT'!D27),0) -> 668.82503 | F22: =IFERROR(ABS('INCOME STATEMENT'!E22/'INCOME STATEMENT'!E27),0) -> 2400.5873 | G22: =AVERAGE(D22:F22) -> 1037.0812
B23: Equity to Total Asset | D23: ='BALANCE SHEET'!C48/'BALANCE SHEET'!C26 -> 0.89153526 | E23: ='BALANCE SHEET'!D48/'BALANCE SHEET'!D26 -> 0.93312369 | F23: ='BALANCE SHEET'!E48/'BALANCE SHEET'!E26 -> 0.79966359 | G23: =AVERAGE(D23:F23) -> 0.87477418
A25: Cash Flow Indicator | B25: Cash Flow Indicator | C25: Column2 | D25: Column3 | E25: Column4 | F25: Column5 | G25: Column6
B26: Operating Cash Flow/Sales | C26: Operating Cash Flow/Sales | D26: ='CASH FLOW STATEMENT'!C11/'INCOME STATEMENT'!C6 -> 0.23858597 | E26: ='CASH FLOW STATEMENT'!D11/'INCOME STATEMENT'!D6 -> 0.062213747 | F26: ='CASH FLOW STATEMENT'!E11/'INCOME STATEMENT'!E6 -> 0.31037228 | G26: =AVERAGE(D26:F26) -> 0.203724
B27: FCF/Operating Cash Ratio | C27: FCF/Operating Cash Flow | D27: =FCF!C20/'CASH FLOW STATEMENT'!C11 -> -3.4984797 | E27: =FCF!D20/'CASH FLOW STATEMENT'!D11 -> 0.74069757 | F27: =FCF!E20/'CASH FLOW STATEMENT'!E11 -> 0.98813098 | G27: =AVERAGE(D27:F27) -> -0.58988372
B28: Short Term Debt Coverage | C28: Operating Cash Flow/Bank Loan Short Term | D28: =IFERROR('CASH FLOW STATEMENT'!C11/'BALANCE SHEET'!C30,0) -> 0 | E28: =IFERROR('CASH FLOW STATEMENT'!D11/'BALANCE SHEET'!D30,0) -> 0 | F28: =IFERROR('CASH FLOW STATEMENT'!E11/'BALANCE SHEET'!E30,0) -> 0 | G28: =AVERAGE(D28:F28) -> 0
B30: Capex Coverage | C30: Operating CF/Capex | D30: =IFERROR(ABS('CASH FLOW STATEMENT'!C11/'CASH FLOW STATEMENT'!C17),0) -> 0.21889965 | E30: =IFERROR(ABS('CASH FLOW STATEMENT'!D11/'CASH FLOW STATEMENT'!D17),0) -> 4.7413328 | F30: =IFERROR(ABS('CASH FLOW STATEMENT'!E11/'CASH FLOW STATEMENT'!E17),0) -> 0 | G30: =AVERAGE(D30:F30) -> 1.6534108

Sheet KEY DRIVERS
A1: =HOME!B4 -> Makmur Jaya Sejati Raya
A2: Key Drivers
A3: Asumsi-asumsi dari Key Drivers Proyeksi Kinerja Keuangan
A4: ='BALANCE SHEET'!A3 -> (IDR)
D6: ='INCOME STATEMENT'!E5+1 -> 2022 | E6: =D6+1 -> 2023 | F6: =E6+1 -> 2024 | G6: =F6+1 -> 2025 | H6: =G6+1 -> 2026 | I6: =H6+1 -> 2027 | J6: =I6+1 -> 2028
A7: Financial Drivers
A8: Interest Rate (Short Term Loan) | C8: 0.14
A9: Interest Rate (Long Term Loan) | C9: 0.12 | M9: tidak usah terlalu dipikirin
A10: Bank Deposit Rate | C10: 0.09
A11: Corporate Tax Rate | C11: 0.22
A13: Operational Drivers
A14: Sales Vol. | C14: unit | D14: 1091700 | E14: =ROUND(D14*(1+E15),-2) -> 1146300 | F14: =ROUND(E14*(1+F15),-2) -> 1260900 | G14: =ROUND(F14*(1+G15),-2) -> 1387000 | H14: =ROUND(G14*(1+H15),-2) -> 1525700 | I14: =ROUND(H14*(1+I15),-2) -> 1678300 | J14: =ROUND(I14*(1+J15),-2) -> 1846100 | M14: tanya manajemen
B15: Increment | E15: 0.05 | F15: 0.1 | G15: 0.1 | H15: 0.1 | I15: 0.1 | J15: 0.1
A17: Sales Price | C17: IDR/unit | D17: 111000 | E17: =ROUNDUP(D17*(1+E18),-3) -> 117000 | F17: =ROUNDUP(E17*(1+F18),-3) -> 123000 | G17: =ROUNDUP(F17*(1+G18),-3) -> 130000 | H17: =ROUNDUP(G17*(1+H18),-3) -> 137000 | I17: =ROUNDUP(H17*(1+I18),-3) -> 144000 | J17: =ROUNDUP(I17*(1+J18),-3) -> 152000
B18: Increment | E18: 0.05 | F18: 0.05 | G18: 0.05 | H18: 0.05 | I18: 0.05 | J18: 0.05 | M18: tanya manajemen
A20: Cost of Goods Sold | C20: %/revenue | D20: ='INCOME STATEMENT'!J7 -> -0.68239332 | E20: =D20 -> -0.68239332 | F20: =E20 -> -0.68239332 | G20: =F20 -> -0.68239332 | H20: =G20 -> -0.68239332 | I20: =H20 -> -0.68239332 | J20: =I20 -> -0.68239332
A22: Operating expense
B23: Selling | C23: %/revenue | D23: ='INCOME STATEMENT'!J12 -> 0 | E23: =D23 -> 0 | F23: =E23 -> 0 | G23: =F23 -> 0 | H23: =G23 -> 0 | I23: =H23 -> 0 | J23: =I23 -> 0 | M23: tanya manajemen, lihat common size, forecasting statistik
B24: G & A | C24: inflation | D24: ='INCOME STATEMENT'!J13 -> -0.15644218 | E24: =D24 -> -0.15644218 | F24: =E24 -> -0.15644218 | G24: =F24 -> -0.15644218 | H24: =G24 -> -0.15644218 | I24: =H24 -> -0.15644218 | J24: =I24 -> -0.15644218
A26: Balance Sheet Drivers
A27: Working Capital:
B28: Acc. Receivable | C28: days | D28: 35 | E28: 35 | F28: 35 | G28: 35 | H28: 35 | I28: 35 | J28: 35
B29: Inventory | C29: days | D29: 50 | E29: 50 | F29: 50 | G29: 50 | H29: 50 | I29: 50 | J29: 50
B30: Account Payable | C30: days | D30: 90 | E30: 90 | F30: 90 | G30: 90 | H30: 90 | I30: 90 | J30: 90
A32: Additional Capex
B33: Land
B34: Building
B35: Equipment | D35: 1000 | E35: 1000 | F35: 1000 | G35: 1000 | H35: 1000 | I35: 1000 | J35: 1000
B36: Others | D36: 500 | E36: 500 | F36: 500 | G36: 500 | H36: 500 | I36: 500 | J36: 500
A37: Total Additional Capex | D37: =SUM(D35:D36) -> 1500 | E37: =SUM(E35:E36) -> 1500 | F37: =SUM(F35:F36) -> 1500 | G37: =SUM(G35:G36) -> 1500 | H37: =SUM(H35:H36) -> 1500 | I37: =SUM(I35:I36) -> 1500 | J37: =SUM(J35:J36) -> 1500

Sheet NOPLAT
A1: =HOME!B4 -> Makmur Jaya Sejati Raya
A2: NOPLAT
A3: ='BALANCE SHEET'!A3 -> (IDR)
C5: ='ACC PAYABLES'!C5 -> 2019 | D5: ='ACC PAYABLES'!D5 -> 2020 | E5: ='ACC PAYABLES'!E5 -> 2021
A7: Profit Before Tax | C7: ='INCOME STATEMENT'!C32 -> 746079045 | D7: ='INCOME STATEMENT'!D32 -> 920799279 | E7: ='INCOME STATEMENT'!E32 -> 2274234874
A8: Add: Interest Expenses | C8: ='INCOME STATEMENT'!C27*-1 -> 16278814 | D8: ='INCOME STATEMENT'!D27*-1 -> 1361128 | E8: ='INCOME STATEMENT'!E27*-1 -> 942033
A9: Less: Interest Income | C9: ='INCOME STATEMENT'!C26*-1 -> -81394069 | D9: ='INCOME STATEMENT'!D26*-1 -> -11803933 | E9: ='INCOME STATEMENT'!E26*-1 -> -13957341
A10: Non Operating Income | C10: ='INCOME STATEMENT'!C30*-1 -> 0 | D10: ='INCOME STATEMENT'!D30*-1 -> 0 | E10: ='INCOME STATEMENT'!E30*-1 -> 212875
A11: EBIT | C11: =SUM(C7:C10) -> 680963790 | D11: =SUM(D7:D10) -> 910356474 | E11: =SUM(E7:E10) -> 2261432441
A13: Statutory Tax on EBIT | C13: =C11*STAT_ASSUMPTIONS!$B$5 -> 1.4981203e+08 | D13: =D11*STAT_ASSUMPTIONS!$B$5 -> 2.0027842e+08 | E13: =E11*STAT_ASSUMPTIONS!$B$5 -> 4.9751514e+08
A14: Tax Shield on Interest Expenses (excluded) | C14: =0 -> 0 | D14: =0 -> 0 | E14: =0 -> 0
A15: Tax on Interest Income (excluded) | C15: =0 -> 0 | D15: =0 -> 0 | E15: =0 -> 0
A16: Tax on Non Operating Income (excluded) | C16: =0 -> 0 | D16: =0 -> 0 | E16: =0 -> 0
A17: Total Taxes on EBIT | C17: =SUM(C13:C16) -> 1.4981203e+08 | D17: =SUM(D13:D16) -> 2.0027842e+08 | E17: =SUM(E13:E16) -> 4.9751514e+08
A19: NOPLAT | C19: =C11-C17 -> 5.3115176e+08 | D19: =D11-D17 -> 7.1007805e+08 | E19: =E11-E17 -> 1.7639173e+09

Sheet FCF
A1: =HOME!B4 -> Makmur Jaya Sejati Raya
A2: Free Cash Flow
A3: ='BALANCE SHEET'!A3 -> (IDR)
C5: =NOPLAT!C5 -> 2019 | D5: =NOPLAT!D5 -> 2020 | E5: =NOPLAT!E5 -> 2021
A7: NOPLAT | C7: =NOPLAT!C19 -> 5.3115176e+08 | D7: =NOPLAT!D19 -> 7.1007805e+08 | E7: =NOPLAT!E19 -> 1.7639173e+09
A8: Add: Depreciation | C8: ='FIXED ASSET'!C51 -> 353481575 | D8: ='FIXED ASSET'!D51 -> 1120799028 | E8: ='FIXED ASSET'!E51 -> 981730341
A9: Gross Cash Flow | C9: =+C7+C8 -> 8.8463333e+08 | D9: =+D7+D8 -> 1.8308771e+09 | E9: =+E7+E8 -> 2.7456476e+09
A11: Changes in Working Capital
A12: (Increase) Decrease in Current Asset | C12: ='CASH FLOW STATEMENT'!C8 -> -248591028 | D12: ='CASH FLOW STATEMENT'!D8 -> -426787292 | E12: ='CASH FLOW STATEMENT'!E8 -> 484323209
A13: Increase (Decrease) in Current Liabilities | C13: ='CASH FLOW STATEMENT'!C9 -> 1746831703 | D13: ='CASH FLOW STATEMENT'!D9 -> -728772103 | E13: ='CASH FLOW STATEMENT'!E9 -> 1880659928
A14: Total Net Changes in Working Capital | C14: ='CASH FLOW STATEMENT'!C10 -> 1498240675 | D14: ='CASH FLOW STATEMENT'!D10 -> -1155559395 | E14: ='CASH FLOW STATEMENT'!E10 -> 2364983137
A16: Less: Capital Expenditures | C16: ='FIXED ASSET'!C23*-1 -> -10175220000 | D16: ='FIXED ASSET'!D23*-1 -> -149675000 | E16: ='FIXED ASSET'!E23*-1 -> 0
A18: Gross Investment | C18: =+C14+C16 -> -8676979325 | D18: =+D14+D16 -> -1305234395 | E18: =+E14+E16 -> 2364983137
A20: Free Cash Flow | C20: =+C9+C18 -> -7.792346e+09 | D20: =+D9+D18 -> 5.2564268e+08 | E20: =+E9+E18 -> 5.1106308e+09

Sheet ROIC
A1: =HOME!B4 -> Makmur Jaya Sejati Raya
A2: ROIC
A3: ='BALANCE SHEET'!A3 -> (IDR)
B5: ='BALANCE SHEET'!C4 -> 2019 | C5: =B5+1 -> 2020 | D5: =C5+1 -> 2021
A7: NOPLAT | B7: =FCF!C20 -> -7.792346e+09 | C7: =FCF!D20 -> 5.2564268e+08 | D7: =FCF!E20 -> 5.1106308e+09
A8: Total Asset in Balance Sheet | B8: ='BALANCE SHEET'!C26 -> 18670530628 | C8: ='BALANCE SHEET'!D26 -> 18410375024 | D8: ='BALANCE SHEET'!E26 -> 17278293031
A9: Less Non Operating Fixed Assets *) | B9: 0 | C9: 0 | D9: 0 | F9: Non-operating fixed assets remain zero unless idle assets are specifically identified.
A10: Less Excess Cash / Cash and Deposit **) | B10: =('BALANCE SHEET'!C8+'BALANCE SHEET'!C9)*-1 -> -419027837 | C10: =('BALANCE SHEET'!D8+'BALANCE SHEET'!D9)*-1 -> -723908969 | D10: =('BALANCE SHEET'!E8+'BALANCE SHEET'!E9)*-1 -> -1054880526 | F10: Cash and bank/deposit treated as excess cash; minimum operating cash remains a judgment sensitivity.
A11: Less Marketable Securities | B11: 0 | C11: 0 | D11: 0
A12: Total Invested Capital at End of Year | B12: =SUM(B8:B11) -> 18251502791 | C12: =SUM(C8:C11) -> 17686466055 | D12: =SUM(D8:D11) -> 16223412505
A13: Total Invested Capital at Beginning of Year | C13: =B12 -> 18251502791 | D13: =C12 -> 17686466055
A15: ROIC = NOPLAT/Inves Capital Beginning of Year | C15: =C7/C13 -> 0.028799967 | D15: =D7/D13 -> 0.28895715
A18: Catatan
A19: *)Book Value Asset yang menganggur (idle) tidak digunakan untuk operasional
A20: **)Asumsi Idle Cash tiap tahun

Sheet KUISIONER
A1: DAFTAR PERTANYAAN UNTUK WAJIB PAJAK
A2: ="Asumsi kondisi "&HOME!B4&" pada saat tanggal Penilaian ("&TEXT(HOME!B20,"dd/mm/yyyy")&")" -> Asumsi kondisi Makmur Jaya Sejati Raya pada saat tanggal Penilaian (31/12/2021)
A5: No. | B5: Pertanyaan
A6: 1 | B6: Apakah terdapat perjanjian dari pemegang saham yang mengatur posisi dalam susunan manajemen perusahaan yang akan menjalankan perusahaan tanpa melihat jumlah kepemilikan saham ?
B7: Jawaban:
B8: a. Ada
B9: b. Tidak ada
A11: 2 | B11: Besarnya kerugian pemegang saham minoritas dari perusahaan tertutup apabila dibandingkan dengan pemegang saham minoritas perusahaan terbuka ?
B12: Jawaban:
B13: a. Rendah
B14: b. Sedang
B15: c. Tinggi
A17: 3 | B17: Hal-hal yang dilakukan oleh pemegang saham pengendali terhadap perusahaan yang dikendalikan untuk membuat saham yang dimilikinya lebih menguntungkan ?
B18: Jawaban:
B19: a. Rendah
B20: b. Moderat
B21: c. Dominan
A23: 4 | B23: Apakah manajemen perusahaan ditunjuk oleh pemegang saham mayoritas ?
B24: Jawaban:
B25: a. Tidak ada
B26: b. Sebagian
B27: c. Seluruhnya
A29: 5 | B29: Apakah pemegang saham mayoritas sebagai pengendali operasional perusahaan ?
B30: Jawaban:
B31: a. Tidak
B32: b. Sebagian
B33: c. Ya
A35: 6 | B35: Apakah telah ada pembatasan atas perijinan usaha, namun banyak investor yang berminat disebabkan prospek usaha dibidang industri tersebut memiliki prospek yang cerah ?
B36: Jawaban:
B37: a. Ada
B38: b. Terbatas
B39: c. Tidak ada
A41: 7 | B41: Apakah untuk industri tersebut membutuhkan skala ekonomis usaha yang besar, sehingga hanya investor tertentu dengan modal besar yang dapat masuk dibidang industri tersebut ?
B42: Jawaban:
B43: a. Tidak terbatas
B44: b. Segmen tertentu
B45: c. Skala besar
A47: 8 | B47: Apakah kebijakan dividen perusahaan telah diputuskan setiap tahun melalui RUPS, serta ada pembagian dividen setiap tahun ?
B48: Jawaban:
B49: a. Ya
...

Sheet DLOC(PFC)
A2: PERTIMBANGAN PREMI FOR CONTROL (PFC)
A4: NO | B4: FAKTOR PERTIMBANGAN | C4: KONDISI PERUSAHAAN DENGAN PEMEGANG SAHAM | D4: KONFIRMASI | E4: NILAI KENDALI
A7: 1 | B7: Perjanjian antara Pemegang Saham | C7: Apakah terdapat perjanjian dari pemegang saham yang mengatur posisi dalam susunan manajemen perusahaan yang akan menjalankan perusahaan tanpa melihat jumlah kepemilikan saham? (Ada/Tidak Ada) | E7: Ada | F7: =IF(E7="Ada",0,1) -> 0 | H7: Ada | I7: Rendah | J7: Rendah | K7: Tidak Ada | L7: Tidak
H8: Tidak Ada | I8: Sedang | J8: Moderat | K8: Sebagian | L8: Sebagian
A9: 2 | B9: Kerugian Saham Minoritas | C9: Besarnya kerugian pemegang saham minoritas dari perusahaan tertutup apabila dibandingkan dengan pemegang saham minoritas perusahaan terbuka? (Rendah, Sedang atau Tinggi) | E9: Rendah | F9: =IF(E9="Rendah",0,IF(E9="Sedang",0.5,1)) -> 0 | I9: Tinggi | J9: Dominan | K9: Seluruhnya | L9: Ya
A11: 3 | B11: Pemegang Saham Pengendali | C11: Hal-hal yang dilakukan oleh pemegang saham pengendali terhadap perusahaan yang dikendalikan untuk membuat saham yang dimilikinya lebih menguntungkan? (Rendah, Moderat atau Dominan) | E11: Rendah | F11: =IF(E11="Rendah",0,IF(E11="Moderat",0.5,1)) -> 0
A13: 4 | B13: Penunjukkan Manajemen | C13: Apakah manajemen perusahaan ditunjuk oleh pemegang saham mayoritas? (Tidak Ada, Sebagian atau Seluruhnya) | E13: Sebagian | F13: =IF(E13="Tidak Ada",0,IF(E13="Sebagian",0.5,1)) -> 0.5
A15: 5 | B15: Pengendalian Operasional Perusahaan | C15: Apakah pemegang saham mayoritas sebagai pengendali operasional perusahaan? (Tidak, Sebagian atau Ya) | E15: Tidak | F15: =IF(E15="Tidak",0,IF(E15="Sebagian",0.5,1)) -> 0
A17: JUMLAH | F17: =SUM(F7:F16) -> 0.5
C19: ="Perhitungan"&" "&E20 -> Perhitungan DLOC
A20: =IF(B20="DLOC Perusahaan tertutup ",1,2) -> 1 | B20: =IF(HOME!B7="tertutup","DLOC Perusahaan tertutup ","DLOC Perusahaan terbuka ") -> DLOC Perusahaan tertutup | C20: Jenis Kepemilikan Saham yang Dinilai | E20: =IF(HOME!B12="Minoritas","DLOC","PFC") -> DLOC
A21: =IF(B31="Minoritas",5,7) -> 7 | B21: Mayoritas
B22: =IF(A20=1," 30% - 70%"," 20% - 35%") -> 30% - 70% | C22: Maksimum Skor | E22: 5
C23: =E20&" "&"Perusahaan Tertutup 30% - 70%" -> DLOC Perusahaan Tertutup 30% - 70% | E23: =RIGHT(B22,3)-LEFT(B22,4) -> 0.4
C24: Jumlah Skor | E24: =F17 -> 0.5
C25: Persentase Perhitungan | E25: =LEFT(B22,4)+(E24/E22*E23) -> 0.34
C26: =E20&" "&"Objek Penilaian" -> DLOC Objek Penilaian | E26: =IF(E20="DLOC",E25,(E25*-1)) -> 0.34
